Workbook

Sheet Data
A1: Order IDs | B1: Date | C1: Item | D1: Sales Rep | E1: Quantity | F1: Price | G1: Total Sales | H1: Commission | I1: Total Commision | J1: State
A2: Order Id = 1 | B2: 43282 | C2: Printer | D2: John | E2: 10 | F2: 80 | G2: 800 | H2: 0.01 | I2: 8 | J2: Meghalaya
A3: Order Id = 2 | B3: 43282 | C3: White Board | D3: Mark | E3: 14 | F3: 40 | G3: 560 | H3: 0.06 | I3: 34 | J3: Uttar Pradesh
A4: Order Id = 3 | B4: 43282 | C4: Office Chair | D4: Mark | E4: 22 | F4: 230 | G4: 5060 | H4: 0.11 | I4: 557 | J4: Maharashtra
A5: Order Id = 4 | B5: 43282 | C5: Office Chair | D5: John | E5: 8 | F5: 230 | G5: 1840 | H5: 0.03 | I5: 55 | J5: Delhi
A6: Order Id = 5 | B6: 43282 | C6: Office Chair | D6: Laura | E6: 12 | F6: 230 | G6: 2760 | H6: 0.03 | I6: 83 | J6: West Bengal
A7: Order Id = 6 | B7: 43282 | C7: Printer | D7: Stacey | E7: 19 | F7: 80 | G7: 1520 | H7: 0.02 | I7: 30 | J7: Bihar
A8: Order Id = 7 | B8: 43282 | C8: Diary | D8: Bob | E8: 17 | F8: 16 | G8: 272 | H8: 0.08 | I8: 22 | J8: Goa
A9: Order Id = 8 | B9: 43282 | C9: Projector | D9: Stacey | E9: 7 | F9: 150 | G9: 1050 | H9: 0.05 | I9: 52 | J9: Karnataka
A10: Order Id = 9 | B10: 43282 | C10: Projector | D10: Stacey | E10: 20 | F10: 150 | G10: 3000 | H10: 0.1 | I10: 300 | J10: Gujarat
A11: Order Id = 10 | B11: 43282 | C11: Diary | D11: John | E11: 21 | F11: 16 | G11: 336 | H11: 0.09 | I11: 30 | J11: Jharkhand
A12: Order Id = 11 | B12: 43282 | C12: Office Chair | D12: Mark | E12: 7 | F12: 230 | G12: 1610 | H12: 0.01 | I12: 16 | J12: Haryana
A13: Order Id = 12 | B13: 43283 | C13: Printer | D13: Stacey | E13: 7 | F13: 80 | G13: 560 | H13: 0.07 | I13: 39 | J13: Kerala
... A1301: Order Id = 1303 | B1301: 43312 | C1301: White Board | D1301: Laura | E1301: 13 | F1301: 40 | G1301: 520 | H1301: 0.02 | I1301: 10 | J1301: Delhi

Sheet KPI
B2: 1 - Total Orders
C3: Count of Order IDs | H3: =C3 -> Count of Order IDs | I3: =C11 -> Total Commision
C4: 1300 | H4: =C4 -> 1300 | I4: =C12 -> 100161
B6: 2 - Total Sales | H6: =C7 -> Sum of Total Sales | I6: Net Sales
C7: Sum of Total Sales | H7: =C8 -> 1585146 | I7: =GETPIVOTDATA("[Measures].[Sum of Total Sales]",$C$7)-GETPIVOTDATA("[Measures].[Sum of Total Commision]",$C$11) -> 1484985
C8: 1585146
B10: 3 - Total Commision
C11: Total Commision
C12: 100161
B14: 4 - Net Sales
C15: =GETPIVOTDATA("[Measures].[Sum of Total Sales]",$C$7)-GETPIVOTDATA("[Measures].[Sum of Total Commision]",$C$11) -> 1484985

Sheet Charts
B2: Total Quantity Sold per product
C4: Row Labels | D4: Sum of Quantity
C5: Diary | D5: 3071
C6: Office Chair | D6: 2648
C7: Printer | D7: 3823
C8: Projector | D8: 3067
C9: White Board | D9: 4027
C10: Grand Total | D10: 16636
B12: Total Sales by Sales Representative
C14: Row Labels | D14: Sum of Total Sales
C15: Bob | D15: 306530
C16: John | D16: 320220
C17: Laura | D17: 307656
C18: Mark | D18: 321258
C19: Stacey | D19: 329482
C20: Grand Total | D20: 1585146
B22: Total Commison by Sales Representative
C24: Row Labels | D24: Sum of Total Commision
C25: Bob | D25: 23569
C26: John | D26: 17876
C27: Laura | D27: 17624
C28: Mark | D28: 21016
C29: Stacey | D29: 20076
C30: Grand Total | D30: 100161
B32: Total Order By State
C33: Row Labels | D33: Count of Order IDs | F33: Pase Using Link
C34: Bihar | D34: 104 | F34: =C34 -> Bihar | G34: =D34 -> 104
C35: Delhi | D35: 105 | F35: =C35 -> Delhi | G35: =D35 -> 105
C36: Goa | D36: 120 | F36: =C36 -> Goa | G36: =D36 -> 120
C37: Gujarat | D37: 163 | F37: =C37 -> Gujarat | G37: =D37 -> 163
C38: Haryana | D38: 68 | F38: =C38 -> Haryana | G38: =D38 -> 68
C39: Jharkhand | D39: 119 | F39: =C39 -> Jharkhand | G39: =D39 -> 119
C40: Karnataka | D40: 119 | F40: =C40 -> Karnataka | G40: =D40 -> 119
C41: Kerala | D41: 68 | F41: =C41 -> Kerala | G41: =D41 -> 68
C42: Maharashtra | D42: 150 | F42: =C42 -> Maharashtra | G42: =D42 -> 150
C43: Meghalaya | D43: 76 | F43: =C43 -> Meghalaya | G43: =D43 -> 76
C44: Uttar Pradesh | D44: 105 | F44: =C44 -> Uttar Pradesh | G44: =D44 -> 105
C45: West Bengal | D45: 103 | F45: =C45 -> West Bengal | G45: =D45 -> 103
C46: Grand Total | D46: 1300
B48: Total Order By Day
...

Sheet Sheet5
H2: =KPI!H3 -> Count of Order IDs | K2: =KPI!I3 -> Total Commision
H3: =KPI!H4 -> 1300 | K3: =KPI!I4 -> 100161
H5: =KPI!H6 -> Sum of Total Sales | K5: =KPI!I6 -> Net Sales
H6: =KPI!H7 -> 1585146 | K6: =KPI!I7 -> 1484985
